<?xml version="1.0" ?>
<!-- =================================================================================== -->
<!-- |    This document was autogenerated by xacro from /home/user/landing_gpu/landing_rl/g_vehicle/car_v2.urdf | -->
<!-- |    EDITING THIS FILE BY HAND IS NOT RECOMMENDED                                 | -->
<!-- =================================================================================== -->
<robot name="car" xmlns:xacro="http://www.ros.org/wiki/xacro">
  <!-- Parameters -->
  <!-- H font thickness (0.005) -->
  <!-- Caution! too small t value can make H invisible in PyBullet -->
  <!-- Base and circle color codes -->
  <!-- Color for PyBullet and RViz -->
  <material name="base_color">
    <color rgba="0.0 1.0 0.0 1.0"/>
  </material>
  <material name="circle_color">
    <color rgba="1.0 1.0 1.0 1.0"/>
  </material>
  <!-- End of parameters -->
  <material name="Red">
    <color rgba="1.0 0 0 1.0"/>
  </material>
  <material name="Green">
    <color rgba="0 1.0 0 1.0"/>
  </material>
  <material name="Blue">
    <color rgba="0 0 1.0 0.5"/>
  </material>
  <material name="Black">
    <color rgba="0 0 0 1.0"/>
  </material>
  <!-- Dummy base link to lift the base up -->
  <link name="base_link">
    <inertial>
      <mass value="0.2"/>
      <origin xyz="0 0 0"/>
      <inertia ixx="0.02" ixy="0.0" ixz="0.0" iyy="0.02" iyz="0.0" izz="0.02"/>
    </inertial>
  </link>
  <!-- Main body -->
  <link name="main_body">
    <inertial>
      <mass value="0.2"/>
      <origin xyz="0 0 0"/>
      <inertia ixx="0.02" ixy="0.0" ixz="0.0" iyy="0.02" iyz="0.0" izz="0.02"/>
    </inertial>
    <visual>
      <origin rpy="0 0 0" xyz="0 0 0"/>
      <geometry>
        <box size="0.3 0.15 0.1"/>
      </geometry>
      <material name="Red"/>
    </visual>
    <collision>
      <origin rpy="0 0 0" xyz="0 0 0"/>
      <geometry>
        <box size="0.3 0.15 0.1"/>
      </geometry>
    </collision>
  </link>
  <gazebo reference="main_body">
    <material>Gazebo/Red</material>
  </gazebo>
  <joint name="dummy" type="fixed">
    <parent link="base_link"/>
    <child link="main_body"/>
    <origin rpy="0 0 0" xyz="0 0 0.16"/>
  </joint>
  <!-- the rear wheel bar -->
  <link name="rear_bar_link">
    <visual>
      <origin xyz="0 0 0"/>
      <geometry>
        <cylinder length="0.175" radius="0.01"/>
      </geometry>
      <material name="Green"/>
    </visual>
    <inertial>
      <mass value="0.01"/>
      <origin xyz="0 0 0"/>
      <inertia ixx="0.01" ixy="0.0" ixz="0.0" iyy="0.01" iyz="0.0" izz="0.01"/>
    </inertial>
    <collision>
      <origin xyz="0 0 0"/>
      <geometry>
        <cylinder length="0.2" radius="0.01"/>
      </geometry>
    </collision>
  </link>
  <gazebo reference="rear_bar_link">
    <material>Gazebo/Green</material>
  </gazebo>
  <joint name="rear_bar_joint" type="continuous">
    <axis xyz="0 0 1"/>
    <parent link="main_body"/>
    <child link="rear_bar_link"/>
    <origin rpy="-1.5707963267948966 0 0" xyz="-0.16 0.0 -0.1"/>
  </joint>
  <!-- the back left wheel -->
  <link name="back_left_wheel_link">
    <inertial>
      <mass value="0.01"/>
      <origin xyz="0 0 0"/>
      <inertia ixx="0.1" ixy="0.0" ixz="0.0" iyy="0.1" iyz="0.0" izz="0.1"/>
    </inertial>
    <visual>
      <origin rpy="1.5707963267948966 0 0" xyz="0 0 0"/>
      <geometry>
        <cylinder length="0.025" radius="0.06"/>
      </geometry>
      <material name="Black"/>
    </visual>
    <collision>
      <origin rpy="1.5707963267948966 0 0" xyz="0 0 0"/>
      <geometry>
        <cylinder length="0.025" radius="0.06"/>
      </geometry>
    </collision>
  </link>
  <gazebo reference="back_left_wheel_link">
    <material>Gazebo/Black</material>
  </gazebo>
  <joint name="back_left_wheel_joint" type="fixed">
    <axis xyz="0 1 0"/>
    <parent link="rear_bar_link"/>
    <child link="back_left_wheel_link"/>
    <origin rpy="1.5707963267948966 0 0" xyz="0.0 0.0 0.1"/>
  </joint>
  <!-- the back right wheel -->
  <link name="back_right_wheel_link">
    <inertial>
      <mass value="0.01"/>
      <origin xyz="0 0 0"/>
      <inertia ixx="0.1" ixy="0.0" ixz="0.0" iyy="0.1" iyz="0.0" izz="0.1"/>
    </inertial>
    <visual>
      <origin rpy="1.5707963267948966 0 0" xyz="0 0 0"/>
      <geometry>
        <cylinder length="0.025" radius="0.06"/>
      </geometry>
      <material name="Black"/>
    </visual>
    <collision>
      <origin rpy="1.5707963267948966 0 0" xyz="0 0 0"/>
      <geometry>
        <cylinder length="0.025" radius="0.06"/>
      </geometry>
    </collision>
  </link>
  <gazebo reference="back_right_wheel_link">
    <material>Gazebo/Black</material>
  </gazebo>
  <joint name="back_right_wheel_joint" type="fixed">
    <axis xyz="0 1 0"/>
    <parent link="rear_bar_link"/>
    <child link="back_right_wheel_link"/>
    <origin rpy="1.5707963267948966 0 0" xyz="0.0 0.0 -0.1"/>
  </joint>
  <!-- The below code is for connected front wheels -->
  <!-- the front wheel bar -->
  <link name="bar_link">
    <visual>
      <origin xyz="0 0 0"/>
      <geometry>
        <cylinder length="0.175" radius="0.01"/>
      </geometry>
      <material name="Green"/>
    </visual>
    <inertial>
      <mass value="0.01"/>
      <origin xyz="0 0 0"/>
      <inertia ixx="0.01" ixy="0.0" ixz="0.0" iyy="0.01" iyz="0.0" izz="0.01"/>
    </inertial>
    <collision>
      <origin xyz="0 0 0"/>
      <geometry>
        <cylinder length="0.2" radius="0.01"/>
      </geometry>
    </collision>
  </link>
  <gazebo reference="bar_link">
    <material>Gazebo/Green</material>
  </gazebo>
  <joint name="bar_joint" type="continuous">
    <axis xyz="0 0 1"/>
    <parent link="main_body"/>
    <child link="bar_link"/>
    <origin rpy="-1.5707963267948966 0 0" xyz="0.16 0.0 -0.1"/>
  </joint>
  <!-- the front left wheel -->
  <link name="front_left_wheel_link">
    <inertial>
      <mass value="0.01"/>
      <origin xyz="0 0 0"/>
      <inertia ixx="0.1" ixy="0.0" ixz="0.0" iyy="0.1" iyz="0.0" izz="0.1"/>
    </inertial>
    <visual>
      <origin rpy="1.5707963267948966 0 0" xyz="0 0 0"/>
      <geometry>
        <cylinder length="0.025" radius="0.06"/>
      </geometry>
      <material name="Black"/>
    </visual>
    <collision>
      <origin rpy="1.5707963267948966 0 0" xyz="0 0 0"/>
      <geometry>
        <cylinder length="0.025" radius="0.06"/>
      </geometry>
    </collision>
  </link>
  <gazebo reference="front_left_wheel_link">
    <material>Gazebo/Green</material>
  </gazebo>
  <joint name="front_left_wheel_joint" type="fixed">
    <parent link="bar_link"/>
    <child link="front_left_wheel_link"/>
    <origin rpy="1.5707963267948966 0 0" xyz="0.0 0.0 -0.1"/>
  </joint>
  <!-- the front right wheel -->
  <link name="front_right_wheel_link">
    <inertial>
      <mass value="0.01"/>
      <origin xyz="0 0 0"/>
      <inertia ixx="0.1" ixy="0.0" ixz="0.0" iyy="0.1" iyz="0.0" izz="0.1"/>
    </inertial>
    <visual>
      <origin rpy="1.5707963267948966 0 0" xyz="0 0 0"/>
      <geometry>
        <cylinder length="0.025" radius="0.06"/>
      </geometry>
      <material name="Black"/>
    </visual>
    <collision>
      <origin rpy="1.5707963267948966 0 0" xyz="0 0 0"/>
      <geometry>
        <cylinder length="0.025" radius="0.06"/>
      </geometry>
    </collision>
  </link>
  <gazebo reference="front_right_wheel_link">
    <material>Gazebo/Green</material>
    <turnGravityOff>false</turnGravityOff>
  </gazebo>
  <joint name="front_right_wheel_joint" type="fixed">
    <parent link="bar_link"/>
    <child link="front_right_wheel_link"/>
    <origin rpy="1.5707963267948966 0 0" xyz="0.0 0.0 0.1"/>
  </joint>
  <!-- the heliport holder -->
  <link name="holder">
    <visual>
      <origin rpy="0 0 0" xyz="0 0 0"/>
      <geometry>
        <cylinder length="0.05" radius="0.005"/>
      </geometry>
      <material name="Black"/>
    </visual>
    <inertial>
      <mass value="0.01"/>
      <origin xyz="0 0 0"/>
      <inertia ixx="0.05" ixy="0.0" ixz="0.0" iyy="0.05" iyz="0.0" izz="0.05"/>
    </inertial>
    <collision>
      <origin rpy="0 0 0" xyz="0 0 0"/>
      <geometry>
        <cylinder length="0.05" radius="0.005"/>
      </geometry>
    </collision>
  </link>
  <gazebo reference="holder">
    <material>Gazebo/Black</material>
  </gazebo>
  <joint name="base_to_holder" type="fixed">
    <parent link="main_body"/>
    <child link="holder"/>
    <origin rpy="0 0 0" xyz="0 0 0.075"/>
  </joint>
  <!-- The heliport base -->
  <link name="heliport_base">
    <visual>
      <origin rpy="0 0 0" xyz="0 0 0"/>
      <geometry>
        <box size="1.0 1.0 0.025"/>
      </geometry>
      <material name="base_color"/>
    </visual>
    <inertial>
      <mass value="0.05"/>
      <origin xyz="0 0 0"/>
      <inertia ixx="0.009" ixy="0.0" ixz="0.0" iyy="0.009" iyz="0.0" izz="0.009"/>
    </inertial>
    <collision>
      <origin rpy="0 0 0" xyz="0 0 0"/>
      <geometry>
        <box size="1.0 1.0 0.025"/>
      </geometry>
    </collision>
  </link>
  <gazebo reference="heliport_base">
    <visual>
      <material>
        <ambient>0 0 1 1.0</ambient>
        <diffuse>0 0.5 0 1.0</diffuse>
        <specular>0 0 0 1.0</specular>
        <emissive>0.0 0.0 0.0 0.0</emissive>
      </material>
    </visual>
  </gazebo>
  <joint name="holder_to_heliport" type="fixed">
    <parent link="holder"/>
    <child link="heliport_base"/>
    <origin rpy="0 0 0" xyz="0 0 0.037500000000000006"/>
  </joint>
  <!-- the heliport circle -->
  <link name="heliport_circle">
    <visual>
      <origin rpy="0 0 0" xyz="0 0 0"/>
      <geometry>
        <cylinder length="0.001" radius="0.35000000000000003"/>
      </geometry>
      <material name="circle_color"/>
    </visual>
    <inertial>
      <mass value="0.00001"/>
      <origin xyz="0 0 0"/>
      <inertia ixx="0.00001" ixy="0.0" ixz="0.0" iyy="0.00001" iyz="0.0" izz="0.00001"/>
    </inertial>
    <collision>
      <origin rpy="0 0 0" xyz="0 0 0"/>
      <geometry>
        <cylinder length="0.001" radius="0.35000000000000003"/>
      </geometry>
    </collision>
  </link>
  <gazebo reference="heliport_circle">
    <visual>
      <material>
        <ambient>0 0 0.5 1.0</ambient>
        <diffuse>1 1 1 1.0</diffuse>
        <specular>0 0 0 1.0</specular>
        <emissive>0.0 0.0 0.0 0.0</emissive>
      </material>
    </visual>
  </gazebo>
  <joint name="heliport_base_to_circle" type="fixed">
    <parent link="heliport_base"/>
    <child link="heliport_circle"/>
    <origin rpy="0 0 0" xyz="0 0 0.013000000000000001"/>
  </joint>
  <!-- left arm of H-->
  <link name="H_left">
    <visual>
      <origin rpy="0 0 0" xyz="0 0 0"/>
      <geometry>
        <box size="0.35000000000000003 0.0823529411764706 0.001"/>
      </geometry>
      <material name="Black"/>
    </visual>
    <inertial>
      <mass value="0.00001"/>
      <origin xyz="0 0 0"/>
      <inertia ixx="0.00001" ixy="0.0" ixz="0.0" iyy="0.00001" iyz="0.0" izz="0.00001"/>
    </inertial>
    <collision>
      <origin rpy="0 0 0" xyz="0 0 0"/>
      <geometry>
        <box size="0.35000000000000003 0.0823529411764706 0.001"/>
      </geometry>
    </collision>
  </link>
  <gazebo reference="H_left">
    <material>Gazebo/Black</material>
  </gazebo>
  <joint name="H_left_to_circle" type="fixed">
    <parent link="heliport_circle"/>
    <child link="H_left"/>
    <origin rpy="0 0 0" xyz="0 0.14411764705882352 0.001"/>
  </joint>
  <!-- right arm of H-->
  <link name="H_right">
    <visual>
      <origin rpy="0 0 0" xyz="0 0 0"/>
      <geometry>
        <box size="0.35000000000000003 0.0823529411764706 0.001"/>
      </geometry>
      <material name="Black"/>
    </visual>
    <inertial>
      <mass value="0.00001"/>
      <origin xyz="0 0 0"/>
      <inertia ixx="0.00001" ixy="0.0" ixz="0.0" iyy="0.00001}" iyz="0.0" izz="0.00001}"/>
    </inertial>
    <collision>
      <origin rpy="0 0 0" xyz="0 0 0"/>
      <geometry>
        <box size="0.35000000000000003 0.0823529411764706 0.001"/>
      </geometry>
    </collision>
  </link>
  <gazebo reference="H_right">
    <material>Gazebo/Black</material>
  </gazebo>
  <joint name="H_right_to_circle" type="fixed">
    <parent link="heliport_circle"/>
    <child link="H_right"/>
    <origin rpy="0 0 0" xyz="0 -0.14411764705882352 0.001"/>
  </joint>
  <!-- middle of H-->
  <link name="H_middle">
    <visual>
      <origin rpy="0 0 0" xyz="0 0 0"/>
      <geometry>
        <box size="0.0823529411764706 0.2058823529411765 0.001"/>
      </geometry>
      <material name="Black"/>
    </visual>
    <inertial>
      <mass value="0.00001"/>
      <origin xyz="0 0 0"/>
      <inertia ixx="0.00001" ixy="0.0" ixz="0.0" iyy="0.00001}" iyz="0.0" izz="0.00001}"/>
    </inertial>
    <collision>
      <origin rpy="0 0 0" xyz="0 0 0"/>
      <geometry>
        <box size="0.0823529411764706 0.2058823529411765 0.001"/>
      </geometry>
    </collision>
  </link>
  <gazebo reference="H_middle">
    <material>Gazebo/Black</material>
  </gazebo>
  <joint name="H_middle_to_circle" type="fixed">
    <parent link="heliport_circle"/>
    <child link="H_middle"/>
    <origin rpy="0 0 0" xyz="0 0 0.001"/>
  </joint>
  <gazebo>
    <plugin filename="libgazebo_ros_planar_move.so" name="object_controller">
      <commandTopic>cmd_vel</commandTopic>
      <odometryTopic>odom</odometryTopic>
      <odometryFrame>odom</odometryFrame>
      <odometryRate>20.0</odometryRate>
      <robotBaseFrame>bar_link</robotBaseFrame>
    </plugin>
  </gazebo>
  <!-- The below code is for free front wheels -->
  <!-- the front left wheel -->
  <!--   <joint name="front_left_wheel_joint" type="continuous">
    <axis xyz="0 1 0"/>
    <parent link="main_body"/>
    <child link="front_left_wheel_link"/>
    <origin rpy="0 0 0" xyz="0.16 0.1 -0.1"/>
  </joint>

  <link name="front_left_wheel_link">
    <xacro:wheel/>
  </link>

  <gazebo reference="front_left_wheel_link">
    <material>Gazebo/Green</material>
  </gazebo> -->
  <!-- the front right wheel -->
  <!--   <joint name="front_right_wheel_joint" type="continuous">
    <axis xyz="0 1 0"/>
    <parent link="main_body"/>
    <child link="front_right_wheel_link"/>
    <origin rpy="0 0 0" xyz="0.16 -0.1 -0.1"/>
  </joint>
  <link name="front_right_wheel_link">
    <xacro:wheel/>
  </link>
  <gazebo reference="front_right_wheel_link">
    <material>Gazebo/Green</material>
    <turnGravityOff>false</turnGravityOff>
  </gazebo> -->
</robot>

